Workbook

Sheet Summary
A1: Sprint Backlog Summary
A2: Auto-reconciled with Project Budget · Total target: 1,236 hours
A4: Sprint | B4: Planning Mode | C4: Tasks | D4: Hours Planned | E4: % of Budget
A5: Sprint 1 | B5: Detailed | C5: 16 | D5: =Backlog!C19 -> 164 | E5: =D5/1236 -> 0.13268608
A6: Sprint 2 | B6: Detailed | C6: 17 | D6: =Backlog!C40 -> 224 | E6: =D6/1236 -> 0.18122977
A7: Sprint 3 | B7: Detailed | C7: 18 | D7: =Backlog!C67 -> 278 | E7: =D7/1236 -> 0.22491909
A8: Sprint 4 | B8: High-level (rolling wave) | C8: 12 | D8: =Backlog!C88 -> 186 | E8: =D8/1236 -> 0.15048544
A9: Sprint 5 | B9: High-level (rolling wave) | C9: 9 | D9: =Backlog!C99 -> 146 | E9: =D9/1236 -> 0.11812298
A10: Total | C10: =SUM(C5:C9) -> 72 | D10: =SUM(D5:D9) -> 998 | E10: =D10/1236 -> 0.80744337
A12: Budget target | D12: 1236
A13: Variance | D13: =D10-D12 -> -238

Sheet Backlog
B1: COMP47360 Research Practicum — Sprint Backlog
B3: Sprint 1
A4: Epic | B4: Task | C4: Estimated Hours | D4: Real Hours | E4: Completion Date | F4: Nancy | G4: Hansel | H4: Alison | I4: Eoin | J4: Sean | K4: Status | L4: Budget Category
A5: PM | B5: Personas & interviews | C5: 16 | D5: 16 | E5: 46167 | F5: TRUE | G5: TRUE | H5: TRUE | I5: TRUE | J5: TRUE | K5: Completed | L5: 1. Requirements & Research
A6: PM | B6: Research competitors | C6: 8 | D6: 6 | E6: 46167 | F6: TRUE | G6: TRUE | H6: TRUE | I6: TRUE | J6: TRUE | K6: Completed | L6: 1. Requirements & Research
A7: PM | B7: Develop early prototypes & mockups | C7: 12 | D7: 12 | E7: 46170 | F7: TRUE | G7: TRUE | H7: TRUE | I7: TRUE | J7: TRUE | K7: Completed | L7: 2. Design (UX/UI)
A8: Infra | B8: Select technologies | C8: 8 | D8: 5 | E8: 46171 | G8: TRUE | H8: TRUE | I8: TRUE | J8: TRUE | K8: Completed | L8: 3. Backend Development
A9: PM | B9: Define user stories & acceptance criteria | C9: 16 | D9: 16 | E9: 46175 | F9: TRUE | K9: Completed | L9: 10. Project Management
A10: PM | B10: Create budget | C10: 10 | D10: 8 | E10: 46171 | F10: TRUE | K10: Completed | L10: 10. Project Management
A11: Infra | B11: Create GitHub Repository | C11: 4 | D11: 5 | E11: 46168 | G11: TRUE | K11: Completed | L11: 9. Deployment & DevOps
A12: Infra | B12: Define Git workflow | C12: 6 | D12: 4 | E12: 46168 | G12: TRUE | K12: Completed | L12: 9. Deployment & DevOps
A13: ML / Data | B13: Crowd data feasibility spike (NYC Open Data) | C13: 24 | D13: 24 | E13: 46178 | H13: TRUE | K13: Completed | L13: 6. ML / Data Engineering
A14: Infra | B14: React-Vite + TypeScript env | C14: 12 | D14: 12 | E14: 46167 | I14: TRUE | K14: Completed | L14: 4. Web Frontend
A15: Infra | B15: Mobile env | C15: 12 | D15: 10 | E15: 46178 | J15: TRUE | K15: Completed | L15: 5. Mobile Development
A16: Auth | B16: Initial frontend structure (no features) | C16: 8 | D16: 8 | E16: 46177 | I16: TRUE | J16: TRUE | K16: Completed | L16: 4. Web Frontend
A17: Infra | B17: Initialise FastAPI backend env | C17: 12 | D17: 12 | E17: 46175 | G17: TRUE | K17: Completed | L17: 3. Backend Development
A18: PM | B18: UX strategy (web vs mobile differentiation) | C18: 16 | D18: 26 | E18: 46176 | F18: TRUE | J18: TRUE | K18: Completed | L18: 2. Design (UX/UI)
B19: Sprint 1 Total | C19: =SUM(C5:C18) -> 164 | D19: =SUM(D5:D18) -> 164
B21: Sprint 2
A22: Epic | B22: Task | C22: Estimated Hours | D22: Real Hours | E22: Completion Date | F22: Nancy | G22: Hansel | H22: Alison | I22: Eoin | J22: Sean | K22: Status | L22: Budget Category
A23: Auth | B23: Auth API setup (Firebase) | C23: 16 | D23: 16 | E23: 46185 | G23: TRUE | K23: Completed | L23: 3. Backend Development
A24: Auth | B24: Auth flow UI (Web) | C24: 12 | D24: 12 | E24: 46189 | I24: TRUE | K24: Completed | L24: 4. Web Frontend
A25: Auth | B25: Bottom navigation component (Web) | C25: 8 | D25: 8 | E25: 46189 | I25: TRUE | K25: Completed | L25: 4. Web Frontend
A26: Auth | B26: Auth flow + Nav (Mobile) | C26: 16 | D26: 16 | E26: 46189 | J26: TRUE | K26: Completed | L26: 5. Mobile Development
A27: Explore | B27: POI database schema + initial 30 POIs | C27: 20 | D27: 20 | E27: 46196 | G27: TRUE | K27: Completed | L27: 3. Backend Development
A28: Explore | B28: GET /pois + GET /poi/{id} endpoints | C28: 12 | D28: 12 | E28: 46189 | G28: TRUE | K28: Completed | L28: 3. Backend Development
A29: Explore | B29: POI popularity flag + Save/Unsave POI API endpoints | C29: 4 | D29: 4 | E29: 46192 | G29: TRUE | K29: Completed | L29: 3. Backend Development
A30: Explore | B30: Explore tab UI + Save icon on POI cards (Web) | C30: 16 | D30: 16 | E30: 46190 | I30: TRUE | K30: Completed | L30: 4. Web Frontend
A31: Explore | B31: POI Detail page UI (Web) | C31: 16 | D31: 16 | E31: 46190 | I31: TRUE | K31: Completed | L31: 4. Web Frontend
A32: Explore | B32: Explore tab + POI Detail (Mobile) | C32: 28 | D32: 24 | E32: 46203 | J32: TRUE | K32: Completed | L32: 5. Mobile Development
A33: ML / Data | B33: Provide data quality report | C33: 16 | D33: 16 | E33: 46190 | H33: TRUE | K33: Completed | L33: 6. ML / Data Engineering
A34: ML / Data | B34: Provide peliminary integrated dataset | C34: 24 | D34: 24 | E34: 46191 | H34: TRUE | K34: Completed | L34: 6. ML / Data Engineering
A35: My Itinerary | B35: My Itinerary tab shell + date picker (Web) | C35: 8 | D35: 8 | E35: 46192 | I35: TRUE | K35: Completed | L35: 4. Web Frontend
A36: My Itinerary | B36: My Itinerary tab shell + date picker (Mobile) | C36: 6 | D36: 6 | E36: 46203 | J36: TRUE | K36: Completed | L36: 5. Mobile Development
A37: PM | B37: Sprint 2 ceremonies + retro | C37: 6 | D37: 6 | E37: 46192 | F37: TRUE | K37: Completed | L37: 10. Project Management
A38: PM | B38: Mid-fidelity wireframes (AI-accelerated, 4 core screens) | C38: 16 | D38: 16 | E38: 46189 | F38: TRUE | K38: Completed | L38: 2. Design (UX/UI)
A39: AI Planner | B39: AI Planner Spike — API + session memory POC | C39: 6 | D39: 6 | E39: 46198 | F39: TRUE | K39: Completed | L39: 6. ML / Data Engineering
B40: Sprint 2 Total | C40: =sum(C23:C38) -> 224 | D40: =sum(D23:D39) -> 226
B42: Sprint 3
A43: Epic | B43: Task | C43: Estimated Hours | D43: Real Hours | E43: Completion Date | F43: Nancy | G43: Hansel | H43: Alison | I43: Eoin | J43: Sean | K43: Status | L43: Budget Category
...

Sheet Burndown chart
A1: Sprint 1 Burndown Chart
A2: Sprint 1: 25 May - 05 Jun 2026 · Total planned: 204h · Working days: 10
A6: Day | B6: Date | C6: Story point | D6: Done Today | E6: Cumulative Done | F6: Actual Remaining
A7: 0 | B7: 46166 | C7: =B20 -> 40 | D7: 0 | E7: 0 | F7: =B20 -> 40
A8: 1 | B8: 46167 | C8: =$B$20-($B$20/10*A8) -> 36 | D8: 8 | E8: =E7+D8 -> 8 | F8: =$F$7-E8 -> 32
A9: 2 | B9: 46168 | C9: =$B$20-($B$20/10*A9) -> 32 | D9: 3 | E9: =E8+D9 -> 11 | F9: =$F$7-E9 -> 29
A10: 3 | B10: 46169 | C10: =$B$20-($B$20/10*A10) -> 28 | D10: 0 | E10: =E9+D10 -> 11 | F10: =$F$7-E10 -> 29
A11: 4 | B11: 46170 | C11: =$B$20-($B$20/10*A11) -> 24 | D11: 3 | E11: =E10+D11 -> 14 | F11: =$F$7-E11 -> 26
A12: 5 | B12: 46171 | C12: =$B$20-($B$20/10*A12) -> 20 | D12: 4 | E12: =E11+D12 -> 18 | F12: =$F$7-E12 -> 22
A13: 6 | B13: 46174 | C13: =$B$20-($B$20/10*A13) -> 16 | D13: 0 | E13: =E12+D13 -> 18 | F13: =$F$7-E13 -> 22
A14: 7 | B14: 46175 | C14: =$B$20-($B$20/10*A14) -> 12 | D14: 5 | E14: =E13+D14 -> 23 | F14: =$F$7-E14 -> 17
A15: 8 | B15: 46176 | C15: =$B$20-($B$20/10*A15) -> 8 | D15: 6 | E15: =E14+D15 -> 29 | F15: =$F$7-E15 -> 11
A16: 9 | B16: 46177 | C16: =$B$20-($B$20/10*A16) -> 4 | D16: 2 | E16: =E15+D16 -> 31 | F16: =$F$7-E16 -> 9
A17: 10 | B17: 46178 | C17: =$B$20-($B$20/10*A17) -> 0 | D17: 9 | E17: =E16+D17 -> 40 | F17: =$F$7-E17 -> 0
A19: Summary
A20: Total Story point | B20: 40
A21: Total Completed | B21: =E17 -> 40
A22: Remaining | B22: =C7-E17 -> 0
A23: Completion % | B23: =E17/C7 -> 1
A53: Sprint 2 Burndown Chart
A54: Sprint 1: 08 Jun 2026 - 19 Jun 2026
A58: Day | B58: Date | C58: Story point | D58: Done Today | E58: Cumulative Done | F58: Actual Remaining
A59: 0 | B59: 46180 | C59: =B72 -> 44 | D59: 0 | E59: 0 | F59: =B72 -> 44
A60: 1 | B60: 46181 | C60: =$B$72-($B$72/10*A60) -> 39.6 | E60: =E59+D60 -> 0 | F60: =$F$59-E60 -> 44
A61: 2 | B61: 46182 | C61: =$B$20-($B$20/10*A61) -> 32 | E61: =E60+D61 -> 0 | F61: =$F$59-E61 -> 44
A62: 3 | B62: 46183 | C62: =$B$20-($B$20/10*A62) -> 28 | E62: =E61+D62 -> 0 | F62: =$F$59-E62 -> 44
A63: 4 | B63: 46184 | C63: =$B$20-($B$20/10*A63) -> 24 | E63: =E62+D63 -> 0 | F63: =$F$59-E63 -> 44
A64: 5 | B64: 46185 | C64: =$B$20-($B$20/10*A64) -> 20 | D64: 3 | E64: =E63+D64 -> 3 | F64: =$F$59-E64 -> 41
A65: 6 | B65: 46188 | C65: =$B$20-($B$20/10*A65) -> 16 | E65: =E64+D65 -> 3 | F65: =$F$59-E65 -> 41
A66: 7 | B66: 46189 | C66: =$B$20-($B$20/10*A66) -> 12 | D66: 12 | E66: =E65+D66 -> 15 | F66: =$F$59-E66 -> 29
A67: 8 | B67: 46190 | C67: =$B$20-($B$20/10*A67) -> 8 | D67: 9 | E67: =E66+D67 -> 24 | F67: =$F$59-E67 -> 20
A68: 9 | B68: 46191 | C68: =$B$20-($B$20/10*A68) -> 4 | D68: 5 | E68: =E67+D68 -> 29 | F68: =$F$59-E68 -> 15
A69: 10 | B69: 46192 | C69: =$B$20-($B$20/10*A69) -> 0 | D69: 4 | E69: =E68+D69 -> 33 | F69: =$F$59-E69 -> 11
A71: Summary
A72: Total Story point | B72: 44
A73: Total Completed | B73: =E69 -> 33
A74: Remaining | B74: =B72-E69 -> 11
A75: Completion % | B75: =E69/C59 -> 0.75
A106: Sprint 3 Burndown Chart
A107: Sprint 1: 22 Jun 2026 - 3 July 2026
...

Sheet Timeline
A1: Gantt Chart
F3: Kickoff | G3: Sprint 1 | I3: Sprint 2 | K3: Sprint 3 | M3: Sprint 4 | O3: Sprint 5 | Q3: Submit
A4: Person | B4: Task | C4: Sprint | D4: Est.h | E4: Status (see Backlog) | F4: W1 18 May | G4: W2 25 May | H4: W3 1 Jun | I4: W4 8 Jun | J4: W5 15 Jun | K4: W6 22 Jun | L4: W7 29 Jun | M4: W8 6 Jul | N4: W9 13 Jul | O4: W10 20 Jul | P4: W11 27 Jul | Q4: W12 3 Aug
A5: Nancy
A6: Nancy | B6: Personas & interviews | C6: Sprint 1 | D6: 16 | G6: ● | H6: ●
A7: Nancy | B7: Research competitors | C7: Sprint 1 | D7: 8 | G7: ● | H7: ●
A8: Nancy | B8: Develop early prototypes & mockups | C8: Sprint 1 | D8: 12 | G8: ● | H8: ●
A9: Nancy | B9: Define user stories & acceptance criteria | C9: Sprint 1 | D9: 16 | G9: ● | H9: ●
A10: Nancy | B10: Create budget | C10: Sprint 1 | D10: 10 | G10: ● | H10: ●
A11: Nancy | B11: UX strategy (web vs mobile differentiation) | C11: Sprint 1 | D11: 16 | G11: ● | H11: ●
A12: Nancy | B12: Mid-fidelity wireframes (4 core screens) | C12: Sprint 2 | D12: 16 | I12: ● | J12: ●
A13: Nancy | B13: Sprint 2 ceremonies + retro | C13: Sprint 2 | D13: 6 | I13: ● | J13: ●
A14: Nancy | B14: High-fi mockups (AI-accelerated, core flow) | C14: Sprint 3 | D14: 10 | K14: ● | L14: ●
A15: Nancy | B15: Polish edge cases + empty states | C15: Sprint 3 | D15: 6 | K15: ● | L15: ●
A16: Nancy | B16: User testing prep + recruitment | C16: Sprint 3 | D16: 4 | K16: ● | L16: ●
A17: Nancy | B17: Sprint 3 ceremonies + retro | C17: Sprint 3 | D17: 6 | K17: ● | L17: ●
A18: Nancy | B18: A/B testing setup + 1 design test | C18: Sprint 4 | D18: 10 | M18: ● | N18: ●
A19: Nancy | B19: User testing sessions (target users) | C19: Sprint 4 | D19: 16 | M19: ● | N19: ●
A20: Nancy | B20: Literature review (parallel, continuous) | C20: Sprint 4 | D20: 20 | M20: ● | N20: ●
A21: Nancy | B21: Sprint 4 ceremonies + retro | C21: Sprint 4 | D21: 6 | M21: ● | N21: ●
A22: Nancy | B22: Demo preparation + rehearsal | C22: Sprint 5 | D22: 16 | O22: ● | P22: ●
A23: Nancy | B23: Final paper writing | C23: Sprint 5 | D23: 40 | O23: ● | P23: ●
A24: Nancy | B24: Documentation cleanup | C24: Sprint 5 | D24: 12 | O24: ● | P24: ●
A25: Nancy | B25: Sprint 5 ceremonies + final retro | C25: Sprint 5 | D25: 6 | O25: ● | P25: ●
A27: Hansel
A28: Hansel | B28: Select technologies | C28: Sprint 1 | D28: 8 | G28: ● | H28: ●
A29: Hansel | B29: Create GitHub Repository | C29: Sprint 1 | D29: 4 | G29: ● | H29: ●
A30: Hansel | B30: Define Git workflow | C30: Sprint 1 | D30: 6 | G30: ● | H30: ●
A31: Hansel | B31: Initialise FastAPI backend env | C31: Sprint 1 | D31: 12 | G31: ● | H31: ●
A32: Hansel | B32: Auth API setup (Firebase) | C32: Sprint 2 | D32: 16 | I32: ● | J32: ●
A33: Hansel | B33: POI database schema + initial 30 POIs | C33: Sprint 2 | D33: 20 | I33: ● | J33: ●
A34: Hansel | B34: GET /pois + GET /poi/{id} endpoints | C34: Sprint 2 | D34: 12 | I34: ● | J34: ●
A35: Hansel | B35: POI popularity flag + Save/Unsave POI API | C35: Sprint 2 | D35: 4 | I35: ● | J35: ●
A36: Hansel | B36: AI Planner Spike — API + session memory POC | C36: Sprint 2 | D36: 6 | I36: ● | J36: ●
A37: Hansel | B37: Itinerary generation core engine (AI scheduling) | C37: Sprint 3 | D37: 20 | K37: ● | L37: ●
A38: Hansel | B38: Crowd data integration + API endpoints | C38: Sprint 3 | D38: 16 | K38: ● | L38: ●
A39: Hansel | B39: 5 POI/day + geographic proximity algorithm | C39: Sprint 3 | D39: 12 | K39: ● | L39: ●
A40: Hansel | B40: Integrate ML predictions with backend | C40: Sprint 3 | D40: 12 | K40: ● | L40: ●
A41: Hansel | B41: AI Planner backend (Gemini + session memory) | C41: Sprint 4 | D41: 16 | M41: ● | N41: ●
A42: Hansel | B42: EC2 & Vercel setup | C42: Sprint 4 | D42: 12 | M42: ● | N42: ●
...

Sheet Budget
A1: Offpeak — Project Budget
A4: Activity | B4: Budget Base (h) | C4: Planned Hours (Backlog Est.) | D4: Actual Hours (Backlog Real) | E4: Variance (Plan−Actual) | F4: % Used | G4: Buffer 30% (h) | H4: Total Budget (h) | I4: Tools / Services | J4: Actual Cost (€) | K4: Budget Cost (€) | L4: Remaining (€)
A5: 1. Requirements & Research | B5: 41 | C5: =SUMIF(Backlog!$L:$L,"1. Requirements & Research",Backlog!$C:$C) -> 44 | D5: =SUMIF(Backlog!$L:$L,"1. Requirements & Research",Backlog!$D:$D) -> 42 | E5: =C5-D5 -> 2 | F5: =IFERROR(D5/C5,0) -> 0.95454545 | G5: =B5*0.3 -> 12.3 | H5: =B5+G5 -> 53.3 | I5: User interviews, competitor reviews, literature review, POI curation | J5: =D5*20 -> 840 | K5: =H5*20 -> 1066 | L5: =K5-J5 -> 226
A6: 2. Design (UX/UI) | B6: 50 | C6: =SUMIF(Backlog!$L:$L,"2. Design (UX/UI)",Backlog!$C:$C) -> 54 | D6: =SUMIF(Backlog!$L:$L,"2. Design (UX/UI)",Backlog!$D:$D) -> 64 | E6: =C6-D6 -> -10 | F6: =IFERROR(D6/C6,0) -> 1.1851852 | G6: =B6*0.3 -> 15 | H6: =B6+G6 -> 65 | I6: Figma (Free Plan) | J6: =D6*20 -> 1280 | K6: =H6*20 -> 1300 | L6: =K6-J6 -> 20
A7: 3. Backend Development | B7: 111 | C7: =SUMIF(Backlog!$L:$L,"3. Backend Development",Backlog!$C:$C) -> 130 | D7: =SUMIF(Backlog!$L:$L,"3. Backend Development",Backlog!$D:$D) -> 127 | E7: =C7-D7 -> 3 | F7: =IFERROR(D7/C7,0) -> 0.97692308 | G7: =B7*0.3 -> 33.3 | H7: =B7+G7 -> 144.3 | I7: Firebase Auth, FastAPI, PostGIS (Free Tier) | J7: =D7*20 -> 2540 | K7: =H7*20 -> 2886 | L7: =K7-J7 -> 346
A8: 4. Web Frontend | B8: 206 | C8: =SUMIF(Backlog!$L:$L,"4. Web Frontend",Backlog!$C:$C) -> 204 | D8: =SUMIF(Backlog!$L:$L,"4. Web Frontend",Backlog!$D:$D) -> 204 | E8: =C8-D8 -> 0 | F8: =IFERROR(D8/C8,0) -> 1 | G8: =B8*0.3 -> 61.8 | H8: =B8+G8 -> 267.8 | I8: React-Vite, Vercel (Free Tier) | J8: =D8*20 -> 4080 | K8: =H8*20 -> 5356 | L8: =K8-J8 -> 1276
A9: 5. Mobile Development | B9: 146 | C9: =SUMIF(Backlog!$L:$L,"5. Mobile Development",Backlog!$C:$C) -> 160 | D9: =SUMIF(Backlog!$L:$L,"5. Mobile Development",Backlog!$D:$D) -> 112 | E9: =C9-D9 -> 48 | F9: =IFERROR(D9/C9,0) -> 0.7 | G9: =B9*0.3 -> 43.8 | H9: =B9+G9 -> 189.8 | I9: React Native / PWA | J9: =D9*20 -> 2240 | K9: =H9*20 -> 3796 | L9: =K9-J9 -> 1556
A10: 6. ML / Data Engineering | B10: 175 | C10: =SUMIF(Backlog!$L:$L,"6. ML / Data Engineering",Backlog!$C:$C) -> 190 | D10: =SUMIF(Backlog!$L:$L,"6. ML / Data Engineering",Backlog!$D:$D) -> 206 | E10: =C10-D10 -> -16 | F10: =IFERROR(D10/C10,0) -> 1.0842105 | G10: =B10*0.3 -> 52.5 | H10: =B10+G10 -> 227.5 | I10: NYC Open Data, Prophet/Pandas (open source), Gemini API | J10: =D10*20 -> 4120 | K10: =H10*20 -> 4550 | L10: =K10-J10 -> 430
A11: 7. Integration | B11: 11 | C11: =SUMIF(Backlog!$L:$L,"7. Integration",Backlog!$C:$C) -> 0 | D11: =SUMIF(Backlog!$L:$L,"7. Integration",Backlog!$D:$D) -> 0 | E11: =C11-D11 -> 0 | F11: =IFERROR(D11/C11,0) -> 0 | G11: =B11*0.3 -> 3.3 | H11: =B11+G11 -> 14.3 | I11: Mapbox Directions API (Free Tier) | J11: =D11*20 -> 0 | K11: =H11*20 -> 286 | L11: =K11-J11 -> 286
A12: 8. Testing & QA | B12: 72 | C12: =SUMIF(Backlog!$L:$L,"8. Testing & QA",Backlog!$C:$C) -> 74 | D12: =SUMIF(Backlog!$L:$L,"8. Testing & QA",Backlog!$D:$D) -> 74 | E12: =C12-D12 -> 0 | F12: =IFERROR(D12/C12,0) -> 1 | G12: =B12*0.3 -> 21.6 | H12: =B12+G12 -> 93.6 | I12: User testing sessions with target users | J12: =D12*20 -> 1480 | K12: =H12*20 -> 1872 | L12: =K12-J12 -> 392
A13: 9. Deployment & DevOps | B13: 31 | C13: =SUMIF(Backlog!$L:$L,"9. Deployment & DevOps",Backlog!$C:$C) -> 34 | D13: =SUMIF(Backlog!$L:$L,"9. Deployment & DevOps",Backlog!$D:$D) -> 33 | E13: =C13-D13 -> 1 | F13: =IFERROR(D13/C13,0) -> 0.97058824 | G13: =B13*0.3 -> 9.3 | H13: =B13+G13 -> 40.3 | I13: AWS EC2 (Free Tier), Vercel hosting | J13: =D13*20 -> 660 | K13: =H13*20 -> 806 | L13: =K13-J13 -> 146
A14: 10. Project Management | B14: 109 | C14: =SUMIF(Backlog!$L:$L,"10. Project Management",Backlog!$C:$C) -> 138 | D14: =SUMIF(Backlog!$L:$L,"10. Project Management",Backlog!$D:$D) -> 136 | E14: =C14-D14 -> 2 | F14: =IFERROR(D14/C14,0) -> 0.98550725 | G14: =B14*0.3 -> 32.7 | H14: =B14+G14 -> 141.7 | I14: Trello, Google Drive, Slack (free), Overleaf (LaTeX) | J14: =D14*20 -> 2720 | K14: =H14*20 -> 2834 | L14: =K14-J14 -> 114
A15: TOTAL | B15: =SUM(B5:B14) -> 952 | C15: =SUM(C5:C14) -> 1028 | D15: =SUM(D5:D14) -> 998 | E15: =C15-D15 -> 30 | F15: =IFERROR(D15/C15,0) -> 0.97081712 | G15: =SUM(G5:G14) -> 285.6 | H15: =SUM(H5:H14) -> 1237.6 | J15: =SUM(J5:J14) -> 19960 | K15: =SUM(K5:K14) -> 24752 | L15: =K15-J15 -> 4792
